2022-12-22 12:27:31,087 -  nornir.core -     INFO -        run() - Running task 'netmiko_send_command' with args {'command_string': 'show version'} on 2 hosts
2022-12-22 12:29:37,853 -  nornir.core -     INFO -        run() - Running task 'netmiko_send_command' with args {'command_string': 'show version'} on 1 hosts
2022-12-22 12:35:11,728 -  nornir.core -     INFO -        run() - Running task 'netmiko_send_command' with args {'command_string': 'show version'} on 1 hosts
2022-12-22 12:50:36,487 -  nornir.core -     INFO -        run() - Running task 'netmiko_send_command' with args {'command_string': 'show int status'} on 1 hosts
2023-01-05 12:32:43,758 -  nornir.core -     INFO -        run() - Running task 'netmiko_send_command' with args {'command_string': 'show int status'} on 1 hosts
2023-01-05 12:34:59,304 -  nornir.core -     INFO -        run() - Running task 'netmiko_send_command' with args {'command_string': 'show int status'} on 1 hosts
2023-01-05 12:35:02,926 - nornir.core.task -    ERROR -      start() - Host 'iosv-1': task 'netmiko_send_command' failed with traceback:
Traceback (most recent call last):
  File "/usr/local/lib/python3.9/dist-packages/netmiko/base_connection.py", line 935, in establish_connection
    self.remote_conn_pre.connect(**ssh_connect_params)
  File "/usr/local/lib/python3.9/dist-packages/paramiko/client.py", line 435, in connect
    self._auth(
  File "/usr/local/lib/python3.9/dist-packages/paramiko/client.py", line 766, in _auth
    raise saved_exception
  File "/usr/local/lib/python3.9/dist-packages/paramiko/client.py", line 753, in _auth
    self._transport.auth_password(username, password)
  File "/usr/local/lib/python3.9/dist-packages/paramiko/transport.py", line 1563, in auth_password
    return self.auth_handler.wait_for_response(my_event)
  File "/usr/local/lib/python3.9/dist-packages/paramiko/auth_handler.py", line 258, in wait_for_response
    raise e
paramiko.ssh_exception.AuthenticationException: Authentication failed.

During handling of the above exception, another exception occurred:

Traceback (most recent call last):
  File "/usr/local/lib/python3.9/dist-packages/nornir/core/task.py", line 99, in start
    r = self.task(self, **self.params)
  File "/usr/local/lib/python3.9/dist-packages/nornir_netmiko/tasks/netmiko_send_command.py", line 26, in netmiko_send_command
    net_connect = task.host.get_connection(CONNECTION_NAME, task.nornir.config)
  File "/usr/local/lib/python3.9/dist-packages/nornir/core/inventory.py", line 494, in get_connection
    self.open_connection(
  File "/usr/local/lib/python3.9/dist-packages/nornir/core/inventory.py", line 546, in open_connection
    conn_obj.open(
  File "/usr/local/lib/python3.9/dist-packages/nornir_netmiko/connections/netmiko.py", line 59, in open
    connection = ConnectHandler(**parameters)
  File "/usr/local/lib/python3.9/dist-packages/netmiko/ssh_dispatcher.py", line 326, in ConnectHandler
    return ConnectionClass(*args, **kwargs)
  File "/usr/local/lib/python3.9/dist-packages/netmiko/cisco/cisco_ios.py", line 17, in __init__
    return super().__init__(*args, **kwargs)
  File "/usr/local/lib/python3.9/dist-packages/netmiko/base_connection.py", line 350, in __init__
    self._open()
  File "/usr/local/lib/python3.9/dist-packages/netmiko/base_connection.py", line 355, in _open
    self.establish_connection()
  File "/usr/local/lib/python3.9/dist-packages/netmiko/base_connection.py", line 972, in establish_connection
    raise NetmikoAuthenticationException(msg)
netmiko.ssh_exception.NetmikoAuthenticationException: Authentication to device failed.

Common causes of this problem are:
1. Invalid username and password
2. Incorrect SSH-key file
3. Connecting to the wrong device

Device settings: cisco_ios 192.168.250.148:22


Authentication failed.

2023-01-09 11:56:53,014 -  nornir.core -     INFO -        run() - Running task 'netmiko_send_command' with args {'command_string': 'show version status'} on 1 hosts
2023-01-09 11:56:58,026 - nornir.core.task -    ERROR -      start() - Host 'iosv-1': task 'netmiko_send_command' failed with traceback:
Traceback (most recent call last):
  File "/usr/local/lib/python3.9/dist-packages/netmiko/base_connection.py", line 935, in establish_connection
    self.remote_conn_pre.connect(**ssh_connect_params)
  File "/usr/local/lib/python3.9/dist-packages/paramiko/client.py", line 349, in connect
    retry_on_signal(lambda: sock.connect(addr))
  File "/usr/local/lib/python3.9/dist-packages/paramiko/util.py", line 283, in retry_on_signal
    return function()
  File "/usr/local/lib/python3.9/dist-packages/paramiko/client.py", line 349, in <lambda>
    retry_on_signal(lambda: sock.connect(addr))
socket.timeout: timed out

During handling of the above exception, another exception occurred:

Traceback (most recent call last):
  File "/usr/local/lib/python3.9/dist-packages/nornir/core/task.py", line 99, in start
    r = self.task(self, **self.params)
  File "/usr/local/lib/python3.9/dist-packages/nornir_netmiko/tasks/netmiko_send_command.py", line 26, in netmiko_send_command
    net_connect = task.host.get_connection(CONNECTION_NAME, task.nornir.config)
  File "/usr/local/lib/python3.9/dist-packages/nornir/core/inventory.py", line 494, in get_connection
    self.open_connection(
  File "/usr/local/lib/python3.9/dist-packages/nornir/core/inventory.py", line 546, in open_connection
    conn_obj.open(
  File "/usr/local/lib/python3.9/dist-packages/nornir_netmiko/connections/netmiko.py", line 59, in open
    connection = ConnectHandler(**parameters)
  File "/usr/local/lib/python3.9/dist-packages/netmiko/ssh_dispatcher.py", line 326, in ConnectHandler
    return ConnectionClass(*args, **kwargs)
  File "/usr/local/lib/python3.9/dist-packages/netmiko/cisco/cisco_ios.py", line 17, in __init__
    return super().__init__(*args, **kwargs)
  File "/usr/local/lib/python3.9/dist-packages/netmiko/base_connection.py", line 350, in __init__
    self._open()
  File "/usr/local/lib/python3.9/dist-packages/netmiko/base_connection.py", line 355, in _open
    self.establish_connection()
  File "/usr/local/lib/python3.9/dist-packages/netmiko/base_connection.py", line 957, in establish_connection
    raise NetmikoTimeoutException(msg)
netmiko.ssh_exception.NetmikoTimeoutException: TCP connection to device failed.

Common causes of this problem are:
1. Incorrect hostname or IP address.
2. Wrong TCP port.
3. Intermediate firewall blocking access.

Device settings: cisco_ios 192.168.250.148:22



2023-01-09 11:59:08,581 -  nornir.core -     INFO -        run() - Running task 'netmiko_send_command' with args {'command_string': 'show version status'} on 1 hosts
2023-01-09 11:59:54,635 -  nornir.core -     INFO -        run() - Running task 'netmiko_send_command' with args {'command_string': 'show version'} on 1 hosts
2023-01-09 12:21:25,036 -  nornir.core -     INFO -        run() - Running task 'netmiko_send_command' with args {'command_string': 'show int status'} on 1 hosts
2023-01-09 13:15:25,296 -  nornir.core -     INFO -        run() - Running task 'netmiko_send_command' with args {'command_string': 'show int status'} on 1 hosts
